Workbook

Sheet groupe
A1: ETU003113 | B1: HARINAMBININA Ranto Luciano
A2: ETU003122 | B2: MILIARASON Harentsoa Michou
A3: ETU003149 | B3: RAKOTOBE Faniry Ntsoa Eva
A4: ETU003216 | B4: RAZAFINDRALAMBO Izakatsimba Herana

Sheet Liste des tâches
A1: Ligne | B1: Catégorie | C1: Module | D1: Taches | E1: Type | F1: Qui | G1: Estimation | H1: Temps passé | I1: Reste à faire | J1: Avancement | K1: Détails (optionnel)
A2: 1 | B2: API Auth, Module Cartes, Module Web | C2: Setup | D2: Intialiser le depot Git | E2: Infrastructure | F2: ETU003216 | G2: 15 | H2: =Detail_avancement!B2 -> 15 | I2: =G2-H2 -> 0 | J2: =(H2/(H2+I2)) -> 1
A3: 2 | B3: API Auth | C3: Setup | D3: Analyse besoins authentification | E3: Analyse | F3: ETU003122 | G3: 15 | H3: =Detail_avancement!B3 -> 15 | I3: =G3-H3 -> 0 | J3: =(H3/(H3+I3)) -> 1
A4: 3 | B4: API Auth | C4: Setup | D4: Configuration environnement Docker | E4: Infrastructure | F4: ETU003122 | G4: 20 | H4: =Detail_avancement!B4 -> 20 | I4: =G4-H4 -> 0 | J4: =(H4/(H4+I4)) -> 1
A5: 4 | B5: API Auth | C5: Setup | D5: Configuration Firebase projet | E5: Infrastructure | F5: ETU003122 | G5: 15 | H5: =Detail_avancement!B5 -> 15 | I5: =G5-H5 -> 0 | J5: =(H5/(H5+I5)) -> 1
A6: 5 | B6: API Auth | C6: Setup | D6: Configuration Base locale Docker | E6: Infrastructure | F6: ETU003122 | G6: 15 | H6: =Detail_avancement!B6 -> 15 | I6: =G6-H6 -> 0 | J6: =(H6/(H6+I6)) -> 1
A7: 6 | B7: API Auth | C7: Setup | D7: Tests connexion Firebase | E7: Tests | F7: ETU003122 | G7: 10 | H7: =Detail_avancement!B7 -> 10 | I7: =G7-H7 -> 0 | J7: =(H7/(H7+I7)) -> 1
A8: 7 | B8: API Auth | C8: Setup | D8: Tests connexion Base locale | E8: Tests | F8: ETU003122 | G8: 10 | H8: =Detail_avancement!B8 -> 10 | I8: =G8-H8 -> 0 | J8: =(H8/(H8+I8)) -> 1
A9: 8 | B9: API Auth | C9: Inscription | D9: Design endpoint inscription | E9: Backend | F9: ETU003113 | G9: 20 | H9: =Detail_avancement!B9 -> 20 | I9: =G9-H9 -> 0 | J9: =(H9/(H9+I9)) -> 1
A10: 9 | B10: API Auth | C10: Inscription | D10: Validation email | E10: Backend | F10: ETU003113 | G10: 15 | H10: =Detail_avancement!B10 -> 15 | I10: =G10-H10 -> 0 | J10: =(H10/(H10+I10)) -> 1
A11: 10 | B11: API Auth | C11: Inscription | D11: Validation mot de passe | E11: Backend | F11: ETU003113 | G11: 15 | H11: =Detail_avancement!B11 -> 15 | I11: =G11-H11 -> 0 | J11: =(H11/(H11+I11)) -> 1
A12: 11 | B12: API Auth | C12: Inscription | D12: Hashage mot de passe | E12: Backend | F12: ETU003113 | G12: 20 | H12: =Detail_avancement!B12 -> 20 | I12: =G12-H12 -> 0 | J12: =(H12/(H12+I12)) -> 1
A13: 12 | B13: API Auth | C13: Inscription | D13: Création compte Firebase | E13: Backend | F13: ETU003113 | G13: 25 | H13: =Detail_avancement!B13 -> 25 | I13: =G13-H13 -> 0 | J13: =(H13/(H13+I13)) -> 1
... A28: 27 | B28: API Auth | C28: Sécurité | D28: Endpoint réinitialisation blocage | E28: Backend | F28: ETU003216 | G28: 20 | H28: =Detail_avancement!B28 -> 20 | I28: =G28-H28 -> 0 | J28: =(H28/(H28+I28)) -> 1
A29: 28 | B29: API Auth | C29: Sécurité | D29: Log tentatives connexion | E29: Backend | F29: ETU003216 | G29: 15 | H29: 15 | I29: =G29-H29 -> 0 | J29: =(H29/(H29+I29)) -> 1
A30: 29 | B30: API Auth | C30: Modification | D30: Sync data profil to firestore | E30: Backend | F30: ETU003216 | G30: 15 | H30: 15 | I30: =G30-H30 -> 0 | J30: =(H30/(H30+I30)) -> 1
A31: 30 | B31: API Auth | C31: Modification | D31: Endpoint modification profil | E31: Backend | F31: ETU003216 | G31: 20 | H31: 20 | I31: =G31-H31 -> 0 | J31: =(H31/(H31+I31)) -> 1
A32: 34 | B32: API Auth | C32: Documentation | D32: Installation Swagger | E32: Documentation | F32: ETU003122 | G32: 2 | H32: =Detail_avancement!B32 -> 2 | I32: =G32-H32 -> 0 | J32: =(H32/(H32+I32)) -> 1
A33: 35 | B33: API Auth | C33: Documentation | D33: Debug Swagger pour laravel PHP | E33: Documentation | F33: ETU003122 | G33: 40 | H33: =Detail_avancement!B33 -> 40 | I33: 0 | J33: =(H33/(H33+I33)) -> 1
A34: 36 | B34: API Auth | C34: Documentation | D34: Documentation endpoint inscription | E34: Documentation | F34: ETU003122 | G34: 5 | H34: =Detail_avancement!B34 -> 5 | I34: =G34-H34 -> 0 | J34: =(H34/(H34+I34)) -> 1
A35: 37 | B35: API Auth | C35: Documentation | D35: Documentation endpoint login | E35: Documentation | F35: ETU003122 | G35: 5 | H35: =Detail_avancement!B35 -> 5 | I35: =G35-H35 -> 0 | J35: =(H35/(H35+I35)) -> 1
A36: 38 | B36: API Auth | C36: Documentation | D36: Documentation endpoint modification | E36: Documentation | F36: ETU003122 | G36: 5 | H36: =Detail_avancement!B36 -> 5 | I36: =G36-H36 -> 0 | J36: =(H36/(H36+I36)) -> 1
A37: 39 | B37: API Auth | C37: Documentation | D37: Exemples requêtes/réponses | E37: Documentation | F37: ETU003122 | G37: 20 | H37: =Detail_avancement!B37 -> 20 | I37: =G37-H37 -> 0 | J37: =(H37/(H37+I37)) -> 1
A38: 40 | B38: Module Cartes | C38: Setup | D38: Analyse des besoins cartographiques | E38: Analyse | F38: ETU003113 | G38: 20 | H38: =Detail_avancement!B38 -> 20 | I38: =G38-H38 -> 0 | J38: =(H38/(H38+I38)) -> 1
A39: 41 | B39: Module Cartes | C39: Setup | D39: Choix des sources cartographiques offline | E39: Analyse | F39: ETU003113 | G39: 15 | H39: =Detail_avancement!B39 -> 15 | I39: =G39-H39 -> 0 | J39: =(H39/(H39+I39)) -> 1
A40: 42 | B40: Module Cartes | C40: Infrastructure | D40: Installation Docker serveur de cartes offline | E40: Infrastructure | F40: ETU003113 | G40: 20 | H40: =Detail_avancement!B40 -> 25 | I40: =G40-H40 -> -5 | J40: =(H40/(H40+I40)) -> 1.25
A41: 43 | B41: Module Cartes | C41: Infrastructure | D41: Configuration stockage tuiles offline | E41: Infrastructure | F41: ETU003113 | G41: 15 | H41: =Detail_avancement!B41 -> 15 | I41: =G41-H41 -> 0 | J41: =(H41/(H41+I41)) -> 1
A42: 44 | B42: Module Cartes | C42: Infrastructure | D42: Téléchargement données Antananarivo | E42: Infrastructure | F42: ETU003113 | G42: 30 | H42: =Detail_avancement!B42 -> 30 | I42: =G42-H42 -> 0 | J42: =(H42/(H42+I42)) -> 1
A43: 45 | B43: Module Cartes | C43: Infrastructure | D43: Génération des tuiles cartographiques | E43: Infrastructure | F43: ETU003113 | G43: 30 | H43: =Detail_avancement!B43 -> 30 | I43: =G43-H43 -> 0 | J43: =(H43/(H43+I43)) -> 1
A44: 46 | B44: Module Cartes | C44: Infrastructure | D44: Test accès API serveur de cartes | E44: Tests | F44: ETU003113 | G44: 15 | H44: =Detail_avancement!B44 -> 15 | I44: =G44-H44 -> 0 | J44: =(H44/(H44+I44)) -> 1
A45: 47 | B45: Module Cartes | C45: Backend | D45: Création module Cartes Laravel | E45: Développement | F45: ETU003149 | G45: 15 | H45: =Detail_avancement!B45 -> 15 | I45: =G45-H45 -> 0 | J45: =(H45/(H45+I45)) -> 1
... A57: 59 | B57: Module Cartes | C57: Maintenance | D57: Plan mise à jour données cartographiques | E57: Maintenance | F57: ETU003216 | G57: 10 | H57: =Detail_avancement!B57 -> 10 | I57: =G57-H57 -> 0 | J57: =(H57/(H57+I57)) -> 1
A58: 60 | B58: Module Web Backend | C58: Conception | D58: Conception base de données | E58: Analyse | F58: ETU003122 | G58: 60 | H58: =Detail_avancement!B58 -> 60 | I58: =G58-H58 -> 0 | J58: =(H58/(H58+I58)) -> 1 | K58: Modélisation des tables PostgreSQL : users, roles, signalements, entreprises, statuts, historiques, relations géographiques (lat/lng), contraintes et index
A59: 61 | B59: Module Web Backend | C59: Setup | D59: Initialisation module API Laravel | E59: Développement | F59: ETU003113 | G59: 20 | H59: =Detail_avancement!B59 -> 20 | I59: =G59-H59 -> 0 | J59: =(H59/(H59+I59)) -> 1 | K59: Structuration du module backend (Controllers, Services, Repositories, Policies)
A60: 62 | B60: Module Web Backend | C60: Setup | D60: Configuration PostgreSQL Docker | E60: Infrastructure | F60: ETU003149 | G60: 20 | H60: =Detail_avancement!B60 -> 20 | I60: =G60-H60 -> 0 | J60: =(H60/(H60+I60)) -> 1 | K60: Configuration du conteneur PostgreSQL, volumes persistants, variables d’environnement Laravel
A61: 63 | B61: Module Web Backend | C61: Auth | D61: Intégration Sanctum (API only) | E61: Développement | F61: ETU003149 | G61: 20 | H61: =Detail_avancement!B61 -> 20 | I61: =G61-H61 -> 0 | J61: =(H61/(H61+I61)) -> 1 | K61: Utilisation de Sanctum pour sécuriser les routes API selon les rôles (visitor, user, manager)
A62: 64 | B62: Module Web Backend | C62: Auth | D62: Connexion Firebase existante | E62: Développement | F62: ETU003113 | G62: 10 | H62: =Detail_avancement!B62 -> 10 | I62: =G62-H62 -> 0 | J62: =(H62/(H62+I62)) -> 1 | K62: Utilisation des tokens Firebase pour l’authentification déjà implémentée
A63: 65 | B63: Module Web Backend | C63: Roles | D63: Gestion des rôles utilisateurs | E63: Développement | F63: ETU003113 | G63: 20 | H63: =Detail_avancement!B63 -> 20 | I63: =G63-H63 -> 0 | J63: =(H63/(H63+I63)) -> 1 | K63: Implémentation des rôles Visiteur, Utilisateur, Manager via policies et middleware
A64: 66 | B64: Module Web Backend | C64: Roles | D64: Compte Manager par défaut | E64: Développement | F64: ETU003113 | G64: 15 | H64: =Detail_avancement!B64 -> 15 | I64: =G64-H64 -> 0 | J64: =(H64/(H64+I64)) -> 1 | K64: Création automatique d’un compte manager lors du déploiement (seeder)
A65: 67 | B65: Module Web Backend | C65: Signalements | D65: Création entité Signalement | E65: Développement | F65: ETU003216 | G65: 30 | H65: =Detail_avancement!B65 -> 45 | I65: =G65-H65 -> -15 | J65: =(H65/(H65+I65)) -> 1.5 | K65: Modèle Signalement : position GPS, statut, date, surface (m²), budget, entreprise, description
...

Sheet Recap
A9: Avancement | B9: =Avancement!D2 -> 1.0907486

Sheet Detail_avancement
A1: {='Liste des tâches'!A:A} -> Ligne | B1: Total | C1: 46048 | D1: 46049 | E1: 46056 | F1: 46058 | G1: 46059 | H1: 46063
A2: 1 | B2: =SUM(C2:AA2) -> 15 | C2: 15
A3: 2 | B3: =SUM(C3:AA3) -> 15 | C3: 15
A4: 3 | B4: =SUM(C4:AA4) -> 20 | C4: 20
A5: 4 | B5: =SUM(C5:AA5) -> 15 | C5: 15
A6: 5 | B6: =SUM(C6:AA6) -> 15 | C6: 15
A7: 6 | B7: =SUM(C7:AA7) -> 10 | C7: 10
A8: 7 | B8: =SUM(C8:AA8) -> 10 | C8: 10
A9: 8 | B9: =SUM(C9:AA9) -> 20 | C9: 20
A10: 9 | B10: =SUM(C10:AA10) -> 15 | C10: 15
A11: 10 | B11: =SUM(C11:AA11) -> 15 | C11: 15
A12: 11 | B12: =SUM(C12:AA12) -> 20 | C12: 20
A13: 12 | B13: =SUM(C13:AA13) -> 25 | C13: 25
... A16: 15 | B16: =SUM(C16:AA16) -> 20 | C16: 20
A17: 16 | B17: =SUM(C17:AA17) -> 20 | C17: 0 | D17: 20
A18: 17 | B18: =SUM(C18:AA18) -> 25 | C18: 0 | D18: 25
A19: 18 | B19: =SUM(C19:AA19) -> 20 | C19: 0 | D19: 20
A20: 19 | B20: =SUM(C20:AA20) -> 25 | C20: 0 | D20: 25
A21: 20 | B21: =SUM(C21:AA21) -> 15 | C21: 0 | D21: 15
A22: 21 | B22: =SUM(C22:AA22) -> 20 | C22: 0 | D22: 20
A23: 22 | B23: =SUM(C23:AA23) -> 25 | C23: 0 | D23: 25
A24: 23 | B24: =SUM(C24:AA24) -> 20 | C24: 0 | D24: 20
A25: 24 | B25: =SUM(C25:AA25) -> 10 | C25: 0 | D25: 10
A26: 25 | B26: =SUM(C26:AA26) -> 5 | C26: 0 | D26: 5
A27: 26 | B27: =SUM(C27:AA27) -> 10 | C27: 0 | D27: 10
A28: 27 | B28: =SUM(C28:AA28) -> 20 | C28: 0 | D28: 20
... A37: 39 | B37: =SUM(C37:AA37) -> 20 | C37: 0 | D37: 20
A38: 40 | B38: =SUM(C38:AA38) -> 20 | C38: 20
A39: 41 | B39: =SUM(C39:AA39) -> 15 | C39: 15
A40: 42 | B40: =SUM(C40:AA40) -> 25 | C40: 25
A41: 43 | B41: =SUM(C41:AA41) -> 15 | C41: 15
A42: 44 | B42: =SUM(C42:AA42) -> 30 | C42: 30
A43: 45 | B43: =SUM(C43:AA43) -> 30 | C43: 30
A44: 46 | B44: =SUM(C44:AA44) -> 15 | C44: 15
A45: 47 | B45: =SUM(C45:AA45) -> 15 | C45: 15
A46: 48 | B46: =SUM(C46:AA46) -> 20 | C46: 20
A47: 49 | B47: =SUM(C47:AA47) -> 25 | C47: 25
A48: 50 | B48: =SUM(C48:AA48) -> 20 | C48: 20
A49: 51 | B49: =SUM(C49:AA49) -> 37 | C49: 37
... A60: 62 | B60: =SUM(C60:AA60) -> 20 | C60: 20
...

Sheet Avancement
A1: estimation total | B1: temps passé total | C1: reste à faire total | D1: avancement | E1: dépassement
A2: =SUM('Liste des tâches'!G:G) -> 2832 | B2: =SUM('Liste des tâches'!H:H) -> 3089 | C2: =SUM('Liste des tâches'!I:I) -> -257 | D2: =(B2/(B2+C2)) -> 1.0907486 | E2: =((B2+C2)-A2)/A2 -> 0
C3: =C2/60 -> -4.2833333 | D3: heure
